<?xml version="1.0" encoding="UTF-8"?>
<!-- Generated by org.testng.reporters.JUnitXMLReporter -->
<testsuite ignored="0" hostname="Administrator" failures="6" tests="19" name="Default test" time="0.278" errors="0" timestamp="2020-06-30T15:29:50 GMT+07:00">
  <testcase classname="testModel.ChuyenDeTest" name="getHinhTest" time="0.011"/>
  <testcase classname="testModel.ChuyenDeTest" name="getHocPhiTest" time="0.002"/>
  <testcase classname="testModel.ChuyenDeTest" name="getMaCDTest" time="0.002"/>
  <testcase classname="testModel.ChuyenDeTest" name="getMoTaTest" time="0.002"/>
  <testcase classname="testModel.ChuyenDeTest" name="getTenCDTest" time="0.002"/>
  <testcase classname="testModel.ChuyenDeTest" name="getThoiLuongTest" time="0.002"/>
  <testcase classname="testModel.ChuyenDeTest" name="setHinhNullTest" time="0.009">
    <failure type="org.testng.TestException" message="
Method ChuyenDeTest.setHinhNullTest()[pri:0, instance:testModel.ChuyenDeTest@5c33f1a9] should have thrown an exception of type class java.lang.Exception">
      <![CDATA[org.testng.TestException: 
Method ChuyenDeTest.setHinhNullTest()[pri:0, instance:testModel.ChuyenDeTest@5c33f1a9] should have thrown an exception of type class java.lang.Exception
at org.testng.internal.ExpectedExceptionsHolder.noException(ExpectedExceptionsHolder.java:82)
at org.testng.internal.TestInvoker.considerExceptions(TestInvoker.java:741)
at org.testng.internal.TestInvoker.invokeMethod(TestInvoker.java:629)
at org.testng.internal.TestInvoker.invokeTestMethod(TestInvoker.java:173)
at org.testng.internal.MethodRunner.runInSequence(MethodRunner.java:46)
at org.testng.internal.TestInvoker$MethodInvocationAgent.invoke(TestInvoker.java:816)
at org.testng.internal.TestInvoker.invokeTestMethods(TestInvoker.java:146)
at org.testng.internal.TestMethodWorker.invokeTestMethods(TestMethodWorker.java:146)
at org.testng.internal.TestMethodWorker.run(TestMethodWorker.java:128)
at java.base/java.util.ArrayList.forEach(ArrayList.java:1510)
at org.testng.TestRunner.privateRun(TestRunner.java:766)
at org.testng.TestRunner.run(TestRunner.java:587)
at org.testng.SuiteRunner.runTest(SuiteRunner.java:384)
at org.testng.SuiteRunner.runSequentially(SuiteRunner.java:378)
at org.testng.SuiteRunner.privateRun(SuiteRunner.java:337)
at org.testng.SuiteRunner.run(SuiteRunner.java:286)
at org.testng.SuiteRunnerWorker.runSuite(SuiteRunnerWorker.java:53)
at org.testng.SuiteRunnerWorker.run(SuiteRunnerWorker.java:96)
at org.testng.TestNG.runSuitesSequentially(TestNG.java:1187)
at org.testng.TestNG.runSuitesLocally(TestNG.java:1109)
at org.testng.TestNG.runSuites(TestNG.java:1039)
at org.testng.TestNG.run(TestNG.java:1007)
at org.testng.remote.AbstractRemoteTestNG.run(AbstractRemoteTestNG.java:115)
at org.testng.remote.RemoteTestNG.initAndRun(RemoteTestNG.java:251)
at org.testng.remote.RemoteTestNG.main(RemoteTestNG.java:77)
]]>
    </failure>
  </testcase> <!-- setHinhNullTest -->
  <testcase classname="testModel.ChuyenDeTest" name="setHinhTest" time="0.002"/>
  <testcase classname="testModel.ChuyenDeTest" name="setHocPhiNegativeTest" time="0.002">
    <failure type="org.testng.TestException" message="
Method ChuyenDeTest.setHocPhiNegativeTest()[pri:0, instance:testModel.ChuyenDeTest@5c33f1a9] should have thrown an exception of type class java.lang.Exception">
      <![CDATA[org.testng.TestException: 
Method ChuyenDeTest.setHocPhiNegativeTest()[pri:0, instance:testModel.ChuyenDeTest@5c33f1a9] should have thrown an exception of type class java.lang.Exception
at org.testng.internal.ExpectedExceptionsHolder.noException(ExpectedExceptionsHolder.java:82)
at org.testng.internal.TestInvoker.considerExceptions(TestInvoker.java:741)
at org.testng.internal.TestInvoker.invokeMethod(TestInvoker.java:629)
at org.testng.internal.TestInvoker.invokeTestMethod(TestInvoker.java:173)
at org.testng.internal.MethodRunner.runInSequence(MethodRunner.java:46)
at org.testng.internal.TestInvoker$MethodInvocationAgent.invoke(TestInvoker.java:816)
at org.testng.internal.TestInvoker.invokeTestMethods(TestInvoker.java:146)
at org.testng.internal.TestMethodWorker.invokeTestMethods(TestMethodWorker.java:146)
at org.testng.internal.TestMethodWorker.run(TestMethodWorker.java:128)
at java.base/java.util.ArrayList.forEach(ArrayList.java:1510)
at org.testng.TestRunner.privateRun(TestRunner.java:766)
at org.testng.TestRunner.run(TestRunner.java:587)
at org.testng.SuiteRunner.runTest(SuiteRunner.java:384)
at org.testng.SuiteRunner.runSequentially(SuiteRunner.java:378)
at org.testng.SuiteRunner.privateRun(SuiteRunner.java:337)
at org.testng.SuiteRunner.run(SuiteRunner.java:286)
at org.testng.SuiteRunnerWorker.runSuite(SuiteRunnerWorker.java:53)
at org.testng.SuiteRunnerWorker.run(SuiteRunnerWorker.java:96)
at org.testng.TestNG.runSuitesSequentially(TestNG.java:1187)
at org.testng.TestNG.runSuitesLocally(TestNG.java:1109)
at org.testng.TestNG.runSuites(TestNG.java:1039)
at org.testng.TestNG.run(TestNG.java:1007)
at org.testng.remote.AbstractRemoteTestNG.run(AbstractRemoteTestNG.java:115)
at org.testng.remote.RemoteTestNG.initAndRun(RemoteTestNG.java:251)
at org.testng.remote.RemoteTestNG.main(RemoteTestNG.java:77)
]]>
    </failure>
  </testcase> <!-- setHocPhiNegativeTest -->
  <testcase classname="testModel.ChuyenDeTest" name="setHocPhiTest" time="0.002"/>
  <testcase classname="testModel.ChuyenDeTest" name="setHocPhiZeroTest" time="0.002">
    <failure type="org.testng.TestException" message="
Method ChuyenDeTest.setHocPhiZeroTest()[pri:0, instance:testModel.ChuyenDeTest@5c33f1a9] should have thrown an exception of type class java.lang.Exception">
      <![CDATA[org.testng.TestException: 
Method ChuyenDeTest.setHocPhiZeroTest()[pri:0, instance:testModel.ChuyenDeTest@5c33f1a9] should have thrown an exception of type class java.lang.Exception
at org.testng.internal.ExpectedExceptionsHolder.noException(ExpectedExceptionsHolder.java:82)
at org.testng.internal.TestInvoker.considerExceptions(TestInvoker.java:741)
at org.testng.internal.TestInvoker.invokeMethod(TestInvoker.java:629)
at org.testng.internal.TestInvoker.invokeTestMethod(TestInvoker.java:173)
at org.testng.internal.MethodRunner.runInSequence(MethodRunner.java:46)
at org.testng.internal.TestInvoker$MethodInvocationAgent.invoke(TestInvoker.java:816)
at org.testng.internal.TestInvoker.invokeTestMethods(TestInvoker.java:146)
at org.testng.internal.TestMethodWorker.invokeTestMethods(TestMethodWorker.java:146)
at org.testng.internal.TestMethodWorker.run(TestMethodWorker.java:128)
at java.base/java.util.ArrayList.forEach(ArrayList.java:1510)
at org.testng.TestRunner.privateRun(TestRunner.java:766)
at org.testng.TestRunner.run(TestRunner.java:587)
at org.testng.SuiteRunner.runTest(SuiteRunner.java:384)
at org.testng.SuiteRunner.runSequentially(SuiteRunner.java:378)
at org.testng.SuiteRunner.privateRun(SuiteRunner.java:337)
at org.testng.SuiteRunner.run(SuiteRunner.java:286)
at org.testng.SuiteRunnerWorker.runSuite(SuiteRunnerWorker.java:53)
at org.testng.SuiteRunnerWorker.run(SuiteRunnerWorker.java:96)
at org.testng.TestNG.runSuitesSequentially(TestNG.java:1187)
at org.testng.TestNG.runSuitesLocally(TestNG.java:1109)
at org.testng.TestNG.runSuites(TestNG.java:1039)
at org.testng.TestNG.run(TestNG.java:1007)
at org.testng.remote.AbstractRemoteTestNG.run(AbstractRemoteTestNG.java:115)
at org.testng.remote.RemoteTestNG.initAndRun(RemoteTestNG.java:251)
at org.testng.remote.RemoteTestNG.main(RemoteTestNG.java:77)
]]>
    </failure>
  </testcase> <!-- setHocPhiZeroTest -->
  <testcase classname="testModel.ChuyenDeTest" name="setMaCDNullTest" time="0.002">
    <failure type="org.testng.TestException" message="
Method ChuyenDeTest.setMaCDNullTest()[pri:0, instance:testModel.ChuyenDeTest@5c33f1a9] should have thrown an exception of type class java.lang.Exception">
      <![CDATA[org.testng.TestException: 
Method ChuyenDeTest.setMaCDNullTest()[pri:0, instance:testModel.ChuyenDeTest@5c33f1a9] should have thrown an exception of type class java.lang.Exception
at org.testng.internal.ExpectedExceptionsHolder.noException(ExpectedExceptionsHolder.java:82)
at org.testng.internal.TestInvoker.considerExceptions(TestInvoker.java:741)
at org.testng.internal.TestInvoker.invokeMethod(TestInvoker.java:629)
at org.testng.internal.TestInvoker.invokeTestMethod(TestInvoker.java:173)
at org.testng.internal.MethodRunner.runInSequence(MethodRunner.java:46)
at org.testng.internal.TestInvoker$MethodInvocationAgent.invoke(TestInvoker.java:816)
at org.testng.internal.TestInvoker.invokeTestMethods(TestInvoker.java:146)
at org.testng.internal.TestMethodWorker.invokeTestMethods(TestMethodWorker.java:146)
at org.testng.internal.TestMethodWorker.run(TestMethodWorker.java:128)
at java.base/java.util.ArrayList.forEach(ArrayList.java:1510)
at org.testng.TestRunner.privateRun(TestRunner.java:766)
at org.testng.TestRunner.run(TestRunner.java:587)
at org.testng.SuiteRunner.runTest(SuiteRunner.java:384)
at org.testng.SuiteRunner.runSequentially(SuiteRunner.java:378)
at org.testng.SuiteRunner.privateRun(SuiteRunner.java:337)
at org.testng.SuiteRunner.run(SuiteRunner.java:286)
at org.testng.SuiteRunnerWorker.runSuite(SuiteRunnerWorker.java:53)
at org.testng.SuiteRunnerWorker.run(SuiteRunnerWorker.java:96)
at org.testng.TestNG.runSuitesSequentially(TestNG.java:1187)
at org.testng.TestNG.runSuitesLocally(TestNG.java:1109)
at org.testng.TestNG.runSuites(TestNG.java:1039)
at org.testng.TestNG.run(TestNG.java:1007)
at org.testng.remote.AbstractRemoteTestNG.run(AbstractRemoteTestNG.java:115)
at org.testng.remote.RemoteTestNG.initAndRun(RemoteTestNG.java:251)
at org.testng.remote.RemoteTestNG.main(RemoteTestNG.java:77)
]]>
    </failure>
  </testcase> <!-- setMaCDNullTest -->
  <testcase classname="testModel.ChuyenDeTest" name="setMaCDTest" time="0.005"/>
  <testcase classname="testModel.ChuyenDeTest" name="setMoTaEmptyTest" time="0.011"/>
  <testcase classname="testModel.ChuyenDeTest" name="setMoTaTest" time="0.002"/>
  <testcase classname="testModel.ChuyenDeTest" name="setTenCDNullTest" time="0.001">
    <failure type="org.testng.TestException" message="
Method ChuyenDeTest.setTenCDNullTest()[pri:0, instance:testModel.ChuyenDeTest@5c33f1a9] should have thrown an exception of type class java.lang.Exception">
      <![CDATA[org.testng.TestException: 
Method ChuyenDeTest.setTenCDNullTest()[pri:0, instance:testModel.ChuyenDeTest@5c33f1a9] should have thrown an exception of type class java.lang.Exception
at org.testng.internal.ExpectedExceptionsHolder.noException(ExpectedExceptionsHolder.java:82)
at org.testng.internal.TestInvoker.considerExceptions(TestInvoker.java:741)
at org.testng.internal.TestInvoker.invokeMethod(TestInvoker.java:629)
at org.testng.internal.TestInvoker.invokeTestMethod(TestInvoker.java:173)
at org.testng.internal.MethodRunner.runInSequence(MethodRunner.java:46)
at org.testng.internal.TestInvoker$MethodInvocationAgent.invoke(TestInvoker.java:816)
at org.testng.internal.TestInvoker.invokeTestMethods(TestInvoker.java:146)
at org.testng.internal.TestMethodWorker.invokeTestMethods(TestMethodWorker.java:146)
at org.testng.internal.TestMethodWorker.run(TestMethodWorker.java:128)
at java.base/java.util.ArrayList.forEach(ArrayList.java:1510)
at org.testng.TestRunner.privateRun(TestRunner.java:766)
at org.testng.TestRunner.run(TestRunner.java:587)
at org.testng.SuiteRunner.runTest(SuiteRunner.java:384)
at org.testng.SuiteRunner.runSequentially(SuiteRunner.java:378)
at org.testng.SuiteRunner.privateRun(SuiteRunner.java:337)
at org.testng.SuiteRunner.run(SuiteRunner.java:286)
at org.testng.SuiteRunnerWorker.runSuite(SuiteRunnerWorker.java:53)
at org.testng.SuiteRunnerWorker.run(SuiteRunnerWorker.java:96)
at org.testng.TestNG.runSuitesSequentially(TestNG.java:1187)
at org.testng.TestNG.runSuitesLocally(TestNG.java:1109)
at org.testng.TestNG.runSuites(TestNG.java:1039)
at org.testng.TestNG.run(TestNG.java:1007)
at org.testng.remote.AbstractRemoteTestNG.run(AbstractRemoteTestNG.java:115)
at org.testng.remote.RemoteTestNG.initAndRun(RemoteTestNG.java:251)
at org.testng.remote.RemoteTestNG.main(RemoteTestNG.java:77)
]]>
    </failure>
  </testcase> <!-- setTenCDNullTest -->
  <testcase classname="testModel.ChuyenDeTest" name="setTenCDTest" time="0.001"/>
  <testcase classname="testModel.ChuyenDeTest" name="setThoiLuongNullTest" time="0.002">
    <failure type="org.testng.TestException" message="
Method ChuyenDeTest.setThoiLuongNullTest()[pri:0, instance:testModel.ChuyenDeTest@5c33f1a9] should have thrown an exception of type class java.lang.Exception">
      <![CDATA[org.testng.TestException: 
Method ChuyenDeTest.setThoiLuongNullTest()[pri:0, instance:testModel.ChuyenDeTest@5c33f1a9] should have thrown an exception of type class java.lang.Exception
at org.testng.internal.ExpectedExceptionsHolder.noException(ExpectedExceptionsHolder.java:82)
at org.testng.internal.TestInvoker.considerExceptions(TestInvoker.java:741)
at org.testng.internal.TestInvoker.invokeMethod(TestInvoker.java:629)
at org.testng.internal.TestInvoker.invokeTestMethod(TestInvoker.java:173)
at org.testng.internal.MethodRunner.runInSequence(MethodRunner.java:46)
at org.testng.internal.TestInvoker$MethodInvocationAgent.invoke(TestInvoker.java:816)
at org.testng.internal.TestInvoker.invokeTestMethods(TestInvoker.java:146)
at org.testng.internal.TestMethodWorker.invokeTestMethods(TestMethodWorker.java:146)
at org.testng.internal.TestMethodWorker.run(TestMethodWorker.java:128)
at java.base/java.util.ArrayList.forEach(ArrayList.java:1510)
at org.testng.TestRunner.privateRun(TestRunner.java:766)
at org.testng.TestRunner.run(TestRunner.java:587)
at org.testng.SuiteRunner.runTest(SuiteRunner.java:384)
at org.testng.SuiteRunner.runSequentially(SuiteRunner.java:378)
at org.testng.SuiteRunner.privateRun(SuiteRunner.java:337)
at org.testng.SuiteRunner.run(SuiteRunner.java:286)
at org.testng.SuiteRunnerWorker.runSuite(SuiteRunnerWorker.java:53)
at org.testng.SuiteRunnerWorker.run(SuiteRunnerWorker.java:96)
at org.testng.TestNG.runSuitesSequentially(TestNG.java:1187)
at org.testng.TestNG.runSuitesLocally(TestNG.java:1109)
at org.testng.TestNG.runSuites(TestNG.java:1039)
at org.testng.TestNG.run(TestNG.java:1007)
at org.testng.remote.AbstractRemoteTestNG.run(AbstractRemoteTestNG.java:115)
at org.testng.remote.RemoteTestNG.initAndRun(RemoteTestNG.java:251)
at org.testng.remote.RemoteTestNG.main(RemoteTestNG.java:77)
]]>
    </failure>
  </testcase> <!-- setThoiLuongNullTest -->
  <testcase classname="testModel.ChuyenDeTest" name="setThoiLuongTest" time="0.001"/>
</testsuite> <!-- Default test -->
