<?xml version="1.0" encoding="UTF-8"?>
<!-- Generated by org.testng.reporters.JUnitReportReporter -->
<testsuite skipped="0" hostname="DESKTOP-V9DJ8HU" name="DAO.ChuyenDeDAOTest" tests="5" failures="0" timestamp="2020-06-20T17:03:15 ICT" time="0.824" errors="2">
  <testcase name="findByIdTest" time="0.058" classname="DAO.ChuyenDeDAOTest"/>
  <system-out/>
  <testcase name="deleteTest" time="0.616" classname="DAO.ChuyenDeDAOTest">
    <error type="org.testng.TestException" message="
The exception was thrown with the wrong message: expected &quot;Khong the xoa khoa ngoai &quot; but got &quot;com.microsoft.sqlserver.jdbc.SQLServerException: The DELETE statement conflicted with the REFERENCE constraint &quot;FK__KhoaHoc__maChuye__182C9B23&quot;. The conflict occurred in database &quot;Poly_Pro&quot;, table &quot;dbo.KhoaHoc&quot;, column &#039;maChuyenDe&#039;.&quot;">
      <![CDATA[org.testng.TestException: 
The exception was thrown with the wrong message: expected "Khong the xoa khoa ngoai " but got "com.microsoft.sqlserver.jdbc.SQLServerException: The DELETE statement conflicted with the REFERENCE constraint "FK__KhoaHoc__maChuye__182C9B23". The conflict occurred in database "Poly_Pro", table "dbo.KhoaHoc", column 'maChuyenDe'."
at org.testng.internal.ExpectedExceptionsHolder.wrongException(ExpectedExceptionsHolder.java:70)
at org.testng.internal.TestInvoker.considerExceptions(TestInvoker.java:736)
at org.testng.internal.TestInvoker.invokeMethod(TestInvoker.java:634)
at org.testng.internal.TestInvoker.invokeTestMethod(TestInvoker.java:174)
at org.testng.internal.MethodRunner.runInSequence(MethodRunner.java:46)
at org.testng.internal.TestInvoker$MethodInvocationAgent.invoke(TestInvoker.java:821)
at org.testng.internal.TestInvoker.invokeTestMethods(TestInvoker.java:147)
at org.testng.internal.TestMethodWorker.invokeTestMethods(TestMethodWorker.java:146)
at org.testng.internal.TestMethodWorker.run(TestMethodWorker.java:128)
at java.util.ArrayList.forEach(Unknown Source)
at org.testng.TestRunner.privateRun(TestRunner.java:767)
at org.testng.TestRunner.run(TestRunner.java:588)
at org.testng.SuiteRunner.runTest(SuiteRunner.java:384)
at org.testng.SuiteRunner.runSequentially(SuiteRunner.java:378)
at org.testng.SuiteRunner.privateRun(SuiteRunner.java:337)
at org.testng.SuiteRunner.run(SuiteRunner.java:286)
at org.testng.SuiteRunnerWorker.runSuite(SuiteRunnerWorker.java:53)
at org.testng.SuiteRunnerWorker.run(SuiteRunnerWorker.java:96)
at org.testng.TestNG.runSuitesSequentially(TestNG.java:1214)
at org.testng.TestNG.runSuitesLocally(TestNG.java:1136)
at org.testng.TestNG.runSuites(TestNG.java:1066)
at org.testng.TestNG.run(TestNG.java:1034)
at org.testng.remote.AbstractRemoteTestNG.run(AbstractRemoteTestNG.java:115)
at org.testng.remote.RemoteTestNG.initAndRun(RemoteTestNG.java:251)
at org.testng.remote.RemoteTestNG.main(RemoteTestNG.java:77)
Caused by: java.lang.RuntimeException: com.microsoft.sqlserver.jdbc.SQLServerException: The DELETE statement conflicted with the REFERENCE constraint "FK__KhoaHoc__maChuye__182C9B23". The conflict occurred in database "Poly_Pro", table "dbo.KhoaHoc", column 'maChuyenDe'.
at Control.JdbcHelper.executeUpdate(JdbcHelper.java:78)
at DAO.ChuyenDeDAO.delete(ChuyenDeDAO.java:49)
at DAO.ChuyenDeDAOTest.deleteTest(ChuyenDeDAOTest.java:45)
at sun.reflect.NativeMethodAccessorImpl.invoke0(Native Method)
at sun.reflect.NativeMethodAccessorImpl.invoke(Unknown Source)
at sun.reflect.DelegatingMethodAccessorImpl.invoke(Unknown Source)
at java.lang.reflect.Method.invoke(Unknown Source)
at org.testng.internal.MethodInvocationHelper.invokeMethod(MethodInvocationHelper.java:135)
at org.testng.internal.TestInvoker.invokeMethod(TestInvoker.java:598)
... 22 more
Caused by: com.microsoft.sqlserver.jdbc.SQLServerException: The DELETE statement conflicted with the REFERENCE constraint "FK__KhoaHoc__maChuye__182C9B23". The conflict occurred in database "Poly_Pro", table "dbo.KhoaHoc", column 'maChuyenDe'.
at com.microsoft.sqlserver.jdbc.SQLServerException.makeFromDatabaseError(SQLServerException.java:258)
at com.microsoft.sqlserver.jdbc.SQLServerStatement.getNextResult(SQLServerStatement.java:1535)
at com.microsoft.sqlserver.jdbc.SQLServerPreparedStatement.doExecutePreparedStatement(SQLServerPreparedStatement.java:467)
at com.microsoft.sqlserver.jdbc.SQLServerPreparedStatement$PrepStmtExecCmd.doExecute(SQLServerPreparedStatement.java:409)
at com.microsoft.sqlserver.jdbc.TDSCommand.execute(IOBuffer.java:7151)
at com.microsoft.sqlserver.jdbc.SQLServerConnection.executeCommand(SQLServerConnection.java:2478)
at com.microsoft.sqlserver.jdbc.SQLServerStatement.executeCommand(SQLServerStatement.java:219)
at com.microsoft.sqlserver.jdbc.SQLServerStatement.executeStatement(SQLServerStatement.java:199)
at com.microsoft.sqlserver.jdbc.SQLServerPreparedStatement.executeUpdate(SQLServerPreparedStatement.java:356)
at Control.JdbcHelper.executeUpdate(JdbcHelper.java:73)
... 30 more
]]>
    </error>
  </testcase> <!-- deleteTest -->
  <system-out/>
  <testcase name="insertTest" time="0.020" classname="DAO.ChuyenDeDAOTest">
    <error type="java.lang.RuntimeException" message="com.microsoft.sqlserver.jdbc.SQLServerException: Violation of PRIMARY KEY constraint &#039;PK__ChuyenDe__74A7AA2DBF3284FF&#039;. Cannot insert duplicate key in object &#039;dbo.ChuyenDe&#039;. The duplicate key value is (CD006).">
      <![CDATA[java.lang.RuntimeException: com.microsoft.sqlserver.jdbc.SQLServerException: Violation of PRIMARY KEY constraint 'PK__ChuyenDe__74A7AA2DBF3284FF'. Cannot insert duplicate key in object 'dbo.ChuyenDe'. The duplicate key value is (CD006).
at Control.JdbcHelper.executeUpdate(JdbcHelper.java:78)
at DAO.ChuyenDeDAO.insert(ChuyenDeDAO.java:25)
at DAO.ChuyenDeDAOTest.insertTest(ChuyenDeDAOTest.java:66)
at sun.reflect.NativeMethodAccessorImpl.invoke0(Native Method)
at sun.reflect.NativeMethodAccessorImpl.invoke(Unknown Source)
at sun.reflect.DelegatingMethodAccessorImpl.invoke(Unknown Source)
at java.lang.reflect.Method.invoke(Unknown Source)
at org.testng.internal.MethodInvocationHelper.invokeMethod(MethodInvocationHelper.java:135)
at org.testng.internal.TestInvoker.invokeMethod(TestInvoker.java:598)
at org.testng.internal.TestInvoker.invokeTestMethod(TestInvoker.java:174)
at org.testng.internal.MethodRunner.runInSequence(MethodRunner.java:46)
at org.testng.internal.TestInvoker$MethodInvocationAgent.invoke(TestInvoker.java:821)
at org.testng.internal.TestInvoker.invokeTestMethods(TestInvoker.java:147)
at org.testng.internal.TestMethodWorker.invokeTestMethods(TestMethodWorker.java:146)
at org.testng.internal.TestMethodWorker.run(TestMethodWorker.java:128)
at java.util.ArrayList.forEach(Unknown Source)
at org.testng.TestRunner.privateRun(TestRunner.java:767)
at org.testng.TestRunner.run(TestRunner.java:588)
at org.testng.SuiteRunner.runTest(SuiteRunner.java:384)
at org.testng.SuiteRunner.runSequentially(SuiteRunner.java:378)
at org.testng.SuiteRunner.privateRun(SuiteRunner.java:337)
at org.testng.SuiteRunner.run(SuiteRunner.java:286)
at org.testng.SuiteRunnerWorker.runSuite(SuiteRunnerWorker.java:53)
at org.testng.SuiteRunnerWorker.run(SuiteRunnerWorker.java:96)
at org.testng.TestNG.runSuitesSequentially(TestNG.java:1214)
at org.testng.TestNG.runSuitesLocally(TestNG.java:1136)
at org.testng.TestNG.runSuites(TestNG.java:1066)
at org.testng.TestNG.run(TestNG.java:1034)
at org.testng.remote.AbstractRemoteTestNG.run(AbstractRemoteTestNG.java:115)
at org.testng.remote.RemoteTestNG.initAndRun(RemoteTestNG.java:251)
at org.testng.remote.RemoteTestNG.main(RemoteTestNG.java:77)
Caused by: com.microsoft.sqlserver.jdbc.SQLServerException: Violation of PRIMARY KEY constraint 'PK__ChuyenDe__74A7AA2DBF3284FF'. Cannot insert duplicate key in object 'dbo.ChuyenDe'. The duplicate key value is (CD006).
at com.microsoft.sqlserver.jdbc.SQLServerException.makeFromDatabaseError(SQLServerException.java:258)
at com.microsoft.sqlserver.jdbc.SQLServerStatement.getNextResult(SQLServerStatement.java:1535)
at com.microsoft.sqlserver.jdbc.SQLServerPreparedStatement.doExecutePreparedStatement(SQLServerPreparedStatement.java:467)
at com.microsoft.sqlserver.jdbc.SQLServerPreparedStatement$PrepStmtExecCmd.doExecute(SQLServerPreparedStatement.java:409)
at com.microsoft.sqlserver.jdbc.TDSCommand.execute(IOBuffer.java:7151)
at com.microsoft.sqlserver.jdbc.SQLServerConnection.executeCommand(SQLServerConnection.java:2478)
at com.microsoft.sqlserver.jdbc.SQLServerStatement.executeCommand(SQLServerStatement.java:219)
at com.microsoft.sqlserver.jdbc.SQLServerStatement.executeStatement(SQLServerStatement.java:199)
at com.microsoft.sqlserver.jdbc.SQLServerPreparedStatement.executeUpdate(SQLServerPreparedStatement.java:356)
at Control.JdbcHelper.executeUpdate(JdbcHelper.java:73)
... 30 more
]]>
    </error>
  </testcase> <!-- insertTest -->
  <system-out/>
  <testcase name="selectTest" time="0.061" classname="DAO.ChuyenDeDAOTest"/>
  <system-out/>
  <testcase name="updateTest" time="0.069" classname="DAO.ChuyenDeDAOTest"/>
  <system-out/>
</testsuite> <!-- DAO.ChuyenDeDAOTest -->
